2019-06-13 11:24:48,900 ERROR: Exception on /favicon.ico [GET] [in /home/andy/python/microblog/venv/lib/python3.6/site-packages/flask/app.py:1780]
Traceback (most recent call last):
  File "/home/andy/python/microblog/venv/lib/python3.6/site-packages/flask/app.py", line 1832, in full_dispatch_request
    rv = self.dispatch_request()
  File "/home/andy/python/microblog/venv/lib/python3.6/site-packages/flask/app.py", line 1810, in dispatch_request
    self.raise_routing_exception(req)
  File "/home/andy/python/microblog/venv/lib/python3.6/site-packages/flask/app.py", line 1793, in raise_routing_exception
    raise request.routing_exception
  File "/home/andy/python/microblog/venv/lib/python3.6/site-packages/flask/ctx.py", line 336, in match_request
    self.url_adapter.match(return_rule=True)
  File "/home/andy/python/microblog/venv/lib/python3.6/site-packages/werkzeug/routing.py", line 1786, in match
    raise NotFound()
werkzeug.exceptions.NotFound: 404 Not Found: The requested URL was not found on the server. If you entered the URL manually please check your spelling and try again.

During handling of the above exception, another exception occurred:

Traceback (most recent call last):
  File "/home/andy/python/microblog/venv/lib/python3.6/site-packages/flask/app.py", line 2311, in wsgi_app
    response = self.full_dispatch_request()
  File "/home/andy/python/microblog/venv/lib/python3.6/site-packages/flask/app.py", line 1834, in full_dispatch_request
    rv = self.handle_user_exception(e)
  File "/home/andy/python/microblog/venv/lib/python3.6/site-packages/flask/app.py", line 1732, in handle_user_exception
    return self.handle_http_exception(e)
  File "/home/andy/python/microblog/venv/lib/python3.6/site-packages/flask/app.py", line 1661, in handle_http_exception
    return handler(e)
  File "/home/andy/python/microblog/app/errors.py", line 6, in not_found_error
    return render_template('404.html'), 404
  File "/home/andy/python/microblog/venv/lib/python3.6/site-packages/flask/templating.py", line 134, in render_template
    return _render(ctx.app.jinja_env.get_or_select_template(template_name_or_list),
  File "/home/andy/python/microblog/venv/lib/python3.6/site-packages/jinja2/environment.py", line 869, in get_or_select_template
    return self.get_template(template_name_or_list, parent, globals)
  File "/home/andy/python/microblog/venv/lib/python3.6/site-packages/jinja2/environment.py", line 830, in get_template
    return self._load_template(name, self.make_globals(globals))
  File "/home/andy/python/microblog/venv/lib/python3.6/site-packages/jinja2/environment.py", line 804, in _load_template
    template = self.loader.load(self, name, globals)
  File "/home/andy/python/microblog/venv/lib/python3.6/site-packages/jinja2/loaders.py", line 125, in load
    code = environment.compile(source, name, filename)
  File "/home/andy/python/microblog/venv/lib/python3.6/site-packages/jinja2/environment.py", line 591, in compile
    self.handle_exception(exc_info, source_hint=source_hint)
  File "/home/andy/python/microblog/venv/lib/python3.6/site-packages/jinja2/environment.py", line 780, in handle_exception
    reraise(exc_type, exc_value, tb)
  File "/home/andy/python/microblog/venv/lib/python3.6/site-packages/jinja2/_compat.py", line 37, in reraise
    raise value.with_traceback(tb)
  File "/home/andy/python/microblog/app/templates/404.html", line 3, in template
    {% block app-content %}
  File "/home/andy/python/microblog/venv/lib/python3.6/site-packages/jinja2/environment.py", line 497, in _parse
    return Parser(self, source, name, encode_filename(filename)).parse()
  File "/home/andy/python/microblog/venv/lib/python3.6/site-packages/jinja2/parser.py", line 901, in parse
    result = nodes.Template(self.subparse(), lineno=1)
  File "/home/andy/python/microblog/venv/lib/python3.6/site-packages/jinja2/parser.py", line 883, in subparse
    rv = self.parse_statement()
  File "/home/andy/python/microblog/venv/lib/python3.6/site-packages/jinja2/parser.py", line 130, in parse_statement
    return getattr(self, 'parse_' + self.stream.current.value)()
  File "/home/andy/python/microblog/venv/lib/python3.6/site-packages/jinja2/parser.py", line 264, in parse_block
    self.fail('Block names in Jinja have to be valid Python '
  File "/home/andy/python/microblog/venv/lib/python3.6/site-packages/jinja2/parser.py", line 59, in fail
    raise exc(msg, lineno, self.name, self.filename)
jinja2.exceptions.TemplateSyntaxError: Block names in Jinja have to be valid Python identifiers and may not contain hyphens, use an underscore instead.
2019-06-13 11:24:51,594 ERROR: Exception on /favicon.ico [GET] [in /home/andy/python/microblog/venv/lib/python3.6/site-packages/flask/app.py:1780]
Traceback (most recent call last):
  File "/home/andy/python/microblog/venv/lib/python3.6/site-packages/flask/app.py", line 1832, in full_dispatch_request
    rv = self.dispatch_request()
  File "/home/andy/python/microblog/venv/lib/python3.6/site-packages/flask/app.py", line 1810, in dispatch_request
    self.raise_routing_exception(req)
  File "/home/andy/python/microblog/venv/lib/python3.6/site-packages/flask/app.py", line 1793, in raise_routing_exception
    raise request.routing_exception
  File "/home/andy/python/microblog/venv/lib/python3.6/site-packages/flask/ctx.py", line 336, in match_request
    self.url_adapter.match(return_rule=True)
  File "/home/andy/python/microblog/venv/lib/python3.6/site-packages/werkzeug/routing.py", line 1786, in match
    raise NotFound()
werkzeug.exceptions.NotFound: 404 Not Found: The requested URL was not found on the server. If you entered the URL manually please check your spelling and try again.

During handling of the above exception, another exception occurred:

Traceback (most recent call last):
  File "/home/andy/python/microblog/venv/lib/python3.6/site-packages/flask/app.py", line 2311, in wsgi_app
    response = self.full_dispatch_request()
  File "/home/andy/python/microblog/venv/lib/python3.6/site-packages/flask/app.py", line 1834, in full_dispatch_request
    rv = self.handle_user_exception(e)
  File "/home/andy/python/microblog/venv/lib/python3.6/site-packages/flask/app.py", line 1732, in handle_user_exception
    return self.handle_http_exception(e)
  File "/home/andy/python/microblog/venv/lib/python3.6/site-packages/flask/app.py", line 1661, in handle_http_exception
    return handler(e)
  File "/home/andy/python/microblog/app/errors.py", line 6, in not_found_error
    return render_template('404.html'), 404
  File "/home/andy/python/microblog/venv/lib/python3.6/site-packages/flask/templating.py", line 134, in render_template
    return _render(ctx.app.jinja_env.get_or_select_template(template_name_or_list),
  File "/home/andy/python/microblog/venv/lib/python3.6/site-packages/jinja2/environment.py", line 869, in get_or_select_template
    return self.get_template(template_name_or_list, parent, globals)
  File "/home/andy/python/microblog/venv/lib/python3.6/site-packages/jinja2/environment.py", line 830, in get_template
    return self._load_template(name, self.make_globals(globals))
  File "/home/andy/python/microblog/venv/lib/python3.6/site-packages/jinja2/environment.py", line 804, in _load_template
    template = self.loader.load(self, name, globals)
  File "/home/andy/python/microblog/venv/lib/python3.6/site-packages/jinja2/loaders.py", line 125, in load
    code = environment.compile(source, name, filename)
  File "/home/andy/python/microblog/venv/lib/python3.6/site-packages/jinja2/environment.py", line 591, in compile
    self.handle_exception(exc_info, source_hint=source_hint)
  File "/home/andy/python/microblog/venv/lib/python3.6/site-packages/jinja2/environment.py", line 780, in handle_exception
    reraise(exc_type, exc_value, tb)
  File "/home/andy/python/microblog/venv/lib/python3.6/site-packages/jinja2/_compat.py", line 37, in reraise
    raise value.with_traceback(tb)
  File "/home/andy/python/microblog/app/templates/404.html", line 3, in template
    {% block app-content %}
  File "/home/andy/python/microblog/venv/lib/python3.6/site-packages/jinja2/environment.py", line 497, in _parse
    return Parser(self, source, name, encode_filename(filename)).parse()
  File "/home/andy/python/microblog/venv/lib/python3.6/site-packages/jinja2/parser.py", line 901, in parse
    result = nodes.Template(self.subparse(), lineno=1)
  File "/home/andy/python/microblog/venv/lib/python3.6/site-packages/jinja2/parser.py", line 883, in subparse
    rv = self.parse_statement()
  File "/home/andy/python/microblog/venv/lib/python3.6/site-packages/jinja2/parser.py", line 130, in parse_statement
    return getattr(self, 'parse_' + self.stream.current.value)()
  File "/home/andy/python/microblog/venv/lib/python3.6/site-packages/jinja2/parser.py", line 264, in parse_block
    self.fail('Block names in Jinja have to be valid Python '
  File "/home/andy/python/microblog/venv/lib/python3.6/site-packages/jinja2/parser.py", line 59, in fail
    raise exc(msg, lineno, self.name, self.filename)
jinja2.exceptions.TemplateSyntaxError: Block names in Jinja have to be valid Python identifiers and may not contain hyphens, use an underscore instead.
