2019-06-18 13:49:35,954 ERROR: Exception on /recipe/Omlette [GET] [in c:\python\git\microblog\winvenv\lib\site-packages\flask\app.py:1780]
Traceback (most recent call last):
  File "c:\python\git\microblog\winvenv\lib\site-packages\flask\app.py", line 2311, in wsgi_app
    response = self.full_dispatch_request()
  File "c:\python\git\microblog\winvenv\lib\site-packages\flask\app.py", line 1834, in full_dispatch_request
    rv = self.handle_user_exception(e)
  File "c:\python\git\microblog\winvenv\lib\site-packages\flask\app.py", line 1737, in handle_user_exception
    reraise(exc_type, exc_value, tb)
  File "c:\python\git\microblog\winvenv\lib\site-packages\flask\_compat.py", line 36, in reraise
    raise value
  File "c:\python\git\microblog\winvenv\lib\site-packages\flask\app.py", line 1832, in full_dispatch_request
    rv = self.dispatch_request()
  File "c:\python\git\microblog\winvenv\lib\site-packages\flask\app.py", line 1818, in dispatch_request
    return self.view_functions[rule.endpoint](**req.view_args)
  File "c:\python\git\microblog\winvenv\lib\site-packages\flask_login\utils.py", line 261, in decorated_view
    return func(*args, **kwargs)
  File "C:\Python\git\microblog\app\routes.py", line 236, in recipe
    ingredients = recipe.ingredients.order_by(name).paginate(
AttributeError: 'InstrumentedList' object has no attribute 'order_by'
2019-06-18 13:58:41,680 INFO: Microblog startup [in C:\Python\git\microblog\app\__init__.py:52]
2019-06-18 13:58:44,729 ERROR: Exception on /recipe/Omlette [GET] [in c:\python\git\microblog\winvenv\lib\site-packages\flask\app.py:1780]
Traceback (most recent call last):
  File "c:\python\git\microblog\winvenv\lib\site-packages\sqlalchemy\engine\base.py", line 1244, in _execute_context
    cursor, statement, parameters, context
  File "c:\python\git\microblog\winvenv\lib\site-packages\sqlalchemy\engine\default.py", line 550, in do_execute
    cursor.execute(statement, parameters)
sqlite3.OperationalError: no such column: ingredient.id

The above exception was the direct cause of the following exception:

Traceback (most recent call last):
  File "c:\python\git\microblog\winvenv\lib\site-packages\flask\app.py", line 2311, in wsgi_app
    response = self.full_dispatch_request()
  File "c:\python\git\microblog\winvenv\lib\site-packages\flask\app.py", line 1834, in full_dispatch_request
    rv = self.handle_user_exception(e)
  File "c:\python\git\microblog\winvenv\lib\site-packages\flask\app.py", line 1737, in handle_user_exception
    reraise(exc_type, exc_value, tb)
  File "c:\python\git\microblog\winvenv\lib\site-packages\flask\_compat.py", line 36, in reraise
    raise value
  File "c:\python\git\microblog\winvenv\lib\site-packages\flask\app.py", line 1832, in full_dispatch_request
    rv = self.dispatch_request()
  File "c:\python\git\microblog\winvenv\lib\site-packages\flask\app.py", line 1818, in dispatch_request
    return self.view_functions[rule.endpoint](**req.view_args)
  File "c:\python\git\microblog\winvenv\lib\site-packages\flask_login\utils.py", line 261, in decorated_view
    return func(*args, **kwargs)
  File "C:\Python\git\microblog\app\routes.py", line 237, in recipe
    page, app.config['POSTS_PER_PAGE'], False)
  File "c:\python\git\microblog\winvenv\lib\site-packages\flask_sqlalchemy\__init__.py", line 496, in paginate
    items = self.limit(per_page).offset((page - 1) * per_page).all()
  File "c:\python\git\microblog\winvenv\lib\site-packages\sqlalchemy\orm\query.py", line 3167, in all
    return list(self)
  File "c:\python\git\microblog\winvenv\lib\site-packages\sqlalchemy\orm\query.py", line 3323, in __iter__
    return self._execute_and_instances(context)
  File "c:\python\git\microblog\winvenv\lib\site-packages\sqlalchemy\orm\query.py", line 3348, in _execute_and_instances
    result = conn.execute(querycontext.statement, self._params)
  File "c:\python\git\microblog\winvenv\lib\site-packages\sqlalchemy\engine\base.py", line 988, in execute
    return meth(self, multiparams, params)
  File "c:\python\git\microblog\winvenv\lib\site-packages\sqlalchemy\sql\elements.py", line 287, in _execute_on_connection
    return connection._execute_clauseelement(self, multiparams, params)
  File "c:\python\git\microblog\winvenv\lib\site-packages\sqlalchemy\engine\base.py", line 1107, in _execute_clauseelement
    distilled_params,
  File "c:\python\git\microblog\winvenv\lib\site-packages\sqlalchemy\engine\base.py", line 1248, in _execute_context
    e, statement, parameters, cursor, context
  File "c:\python\git\microblog\winvenv\lib\site-packages\sqlalchemy\engine\base.py", line 1466, in _handle_dbapi_exception
    util.raise_from_cause(sqlalchemy_exception, exc_info)
  File "c:\python\git\microblog\winvenv\lib\site-packages\sqlalchemy\util\compat.py", line 383, in raise_from_cause
    reraise(type(exception), exception, tb=exc_tb, cause=cause)
  File "c:\python\git\microblog\winvenv\lib\site-packages\sqlalchemy\util\compat.py", line 128, in reraise
    raise value.with_traceback(tb)
  File "c:\python\git\microblog\winvenv\lib\site-packages\sqlalchemy\engine\base.py", line 1244, in _execute_context
    cursor, statement, parameters, context
  File "c:\python\git\microblog\winvenv\lib\site-packages\sqlalchemy\engine\default.py", line 550, in do_execute
    cursor.execute(statement, parameters)
sqlalchemy.exc.OperationalError: (sqlite3.OperationalError) no such column: ingredient.id
[SQL: SELECT post.id AS post_id, post.body AS post_body, post.timestamp AS post_timestamp, post.user_id AS post_user_id, post.language AS post_language 
FROM post JOIN ingredients_list ON ingredients_list.ingredient_id = ingredient.id 
WHERE ingredients_list.recipe_id = ? ORDER BY ingredient.name
 LIMIT ? OFFSET ?]
[parameters: (2, 10, 0)]
(Background on this error at: http://sqlalche.me/e/e3q8)
2019-06-18 13:59:34,220 INFO: Microblog startup [in C:\Python\git\microblog\app\__init__.py:52]
2019-06-18 14:00:06,285 INFO: Microblog startup [in C:\Python\git\microblog\app\__init__.py:52]
2019-06-18 14:03:36,068 INFO: Microblog startup [in C:\Python\git\microblog\app\__init__.py:52]
